<?xml version="1.0"?>
<robot name="my_robot" xmlns:xacro="http://ros.org/wiki/xacro">

  <!-- ── Base link ─────────────────────────────────── -->
  <link name="base_footprint"/>

  <joint name="base_joint" type="fixed">
    <parent link="base_footprint"/>
    <child link="base_link"/>
    <origin xyz="0 0 0.05"/>
  </joint>

  <link name="base_link">
    <visual>
      <geometry><box size="0.4 0.3 0.1"/></geometry>
      <material name="blue"><color rgba="0.2 0.4 0.8 1"/></material>
    </visual>
    <collision>
      <geometry><box size="0.4 0.3 0.1"/></geometry>
    </collision>
    <inertial>
      <mass value="5.0"/>
      <inertia ixx="0.05" iyy="0.05" izz="0.08" ixy="0" ixz="0" iyz="0"/>
    </inertial>
  </link>

  <!-- ── Camera link ───────────────────────────────── -->
  <!-- mounted 15 cm forward, 15 cm above base_link center -->
  <joint name="camera_joint" type="fixed">
    <parent link="base_link"/>
    <child link="camera_link"/>
    <origin xyz="0.15 0 0.15" rpy="0 0 0"/>
  </joint>

  <link name="camera_link">
    <visual>
      <geometry><box size="0.05 0.09 0.03"/></geometry>
      <material name="black"><color rgba="0.1 0.1 0.1 1"/></material>
    </visual>
    <collision>
      <geometry><box size="0.05 0.09 0.03"/></geometry>
    </collision>
    <inertial>
      <mass value="0.1"/>
      <inertia ixx="0.001" iyy="0.001" izz="0.001" ixy="0" ixz="0" iyz="0"/>
    </inertial>
  </link>

  <!-- optical frame: Z-forward convention for Gazebo camera plugin -->
  <joint name="camera_optical_joint" type="fixed">
    <parent link="camera_link"/>
    <child link="camera_optical_link"/>
    <origin xyz="0 0 0" rpy="-1.5708 0 -1.5708"/>
  </joint>
  <link name="camera_optical_link"/>

  <!-- ── Gazebo depth camera plugin ───────────────── -->
  <gazebo reference="camera_link">
    <sensor name="depth_camera" type="depth">
      <update_rate>30</update_rate>
      <camera>
        <horizontal_fov>1.5</horizontal_fov>
        <image>
          <width>640</width>
          <height>480</height>
          <format>R8G8B8</format>
        </image>
        <clip>
          <near>0.2</near>
          <far>10.0</far>
        </clip>
      </camera>
      <plugin name="depth_camera_plugin" filename="libgazebo_ros_camera.so">
        <ros>
          <remapping>~/image_raw:=/camera/color/image_raw</remapping>
          <remapping>~/depth/image_raw:=/camera/depth/image_raw</remapping>
          <remapping>~/points:=/camera/depth/points</remapping>
          <remapping>~/camera_info:=/camera/color/camera_info</remapping>
          <remapping>~/depth/camera_info:=/camera/depth/camera_info</remapping>
        </ros>
        <frame_name>camera_optical_link</frame_name>
        <min_depth>0.2</min_depth>
        <max_depth>10.0</max_depth>
      </plugin>
    </sensor>
  </gazebo>

  <!-- ── Differential drive plugin ────────────────── -->
  <gazebo>
    <plugin name="diff_drive" filename="libgazebo_ros_diff_drive.so">
      <ros>
        <remapping>cmd_vel:=/cmd_vel</remapping>
        <remapping>odom:=/odom</remapping>
      </ros>
      <left_joint>left_wheel_joint</left_joint>
      <right_joint>right_wheel_joint</right_joint>
      <wheel_separation>0.3</wheel_separation>
      <wheel_diameter>0.1</wheel_diameter>
      <max_wheel_torque>20</max_wheel_torque>
      <max_wheel_acceleration>2.0</max_wheel_acceleration>
      <publish_odom>true</publish_odom>
      <publish_odom_tf>true</publish_odom_tf>
      <publish_wheel_tf>false</publish_wheel_tf>
      <odometry_frame>odom</odometry_frame>
      <robot_base_frame>base_footprint</robot_base_frame>
    </plugin>
  </gazebo>

  <!-- ── Left wheel ────────────────────────────────── -->
  <link name="left_wheel">
    <visual>
      <geometry><cylinder radius="0.05" length="0.04"/></geometry>
      <material name="dark"><color rgba="0.2 0.2 0.2 1"/></material>
    </visual>
    <collision>
      <geometry><cylinder radius="0.05" length="0.04"/></geometry>
    </collision>
    <inertial>
      <mass value="0.5"/>
      <inertia ixx="0.003" iyy="0.003" izz="0.005" ixy="0" ixz="0" iyz="0"/>
    </inertial>
  </link>
  <joint name="left_wheel_joint" type="continuous">
    <parent link="base_link"/>
    <child link="left_wheel"/>
    <origin xyz="0 0.17 -0.05" rpy="-1.5708 0 0"/>
    <axis xyz="0 0 1"/>
  </joint>

  <!-- ── Right wheel ───────────────────────────────── -->
  <link name="right_wheel">
    <visual>
      <geometry><cylinder radius="0.05" length="0.04"/></geometry>
      <material name="dark2"><color rgba="0.2 0.2 0.2 1"/></material>
    </visual>
    <collision>
      <geometry><cylinder radius="0.05" length="0.04"/></geometry>
    </collision>
    <inertial>
      <mass value="0.5"/>
      <inertia ixx="0.003" iyy="0.003" izz="0.005" ixy="0" ixz="0" iyz="0"/>
    </inertial>
  </link>
  <joint name="right_wheel_joint" type="continuous">
    <parent link="base_link"/>
    <child link="right_wheel"/>
    <origin xyz="0 -0.17 -0.05" rpy="-1.5708 0 0"/>
    <axis xyz="0 0 1"/>
  </joint>

  <!-- ── Caster (front, passive) ───────────────────── -->
  <link name="caster">
    <visual><geometry><sphere radius="0.025"/></geometry></visual>
    <collision><geometry><sphere radius="0.025"/></geometry></collision>
    <inertial>
      <mass value="0.1"/>
      <inertia ixx="0.0001" iyy="0.0001" izz="0.0001" ixy="0" ixz="0" iyz="0"/>
    </inertial>
  </link>
  <joint name="caster_joint" type="fixed">
    <parent link="base_link"/>
    <child link="caster"/>
    <origin xyz="0.15 0 -0.075"/>
  </joint>
  <gazebo reference="caster">
    <mu1>0.0</mu1>
    <mu2>0.0</mu2>
  </gazebo>

</robot>
